Workbook

Sheet Normas y Grupos
B2: NORMAS
B4: · Se deben seleccionar 7 equipos en total, como se explica en el apartado 1. (Informadlos en la Hoja "Participantes")
B5: · Una vez todos los participantes hayan seleccionado sus equipo cada equipo puntuará x puntos por jornada en función de las normas del apartado 2.
B6: · Al final del torneo, el jugador que sume mas puntos entre todos sus equipos será el Ganador de la porra.
B7: · El reparto de premios será una porporción del Bote acumulado: 75% el ganador 20% El segundo 5% el tercero (En caso de empate se repartirá el premio correspondiente)
B8: · La inscripción será de 10€ por paticipante
B10: 1 - Selección de Equipos para la porra
B11: Elegir:
B12: 1 equipo del Grupo 1 (TOP)
B13: 3 equipos del Grupo 2 (BUENOS)
B14: 2 equipos del Grupo 3 (NORMALES)
B15: 1 equipo del Grupo 4 (SORPRESAS)
B17: 2- Puntuaciones por Equipo
B19: Por cada gol marcado - 1 pto | G19: Puntos por partido
B20: Por partido ganado - 3 ptos (no cuenta prórroga)
B21: Por partido empatado - 1 pto (no cuenta prórroga)
B22: Por pasar de fase - 6 ptos | G22: Puntos Extra
B23: Por ganar campeonato - 10 ptos
B24: Pichichi Mundial - 8 ptos (que este en tu equipo)
B25: Equipo menos goleado - 6 ptos (solo semifinalistas)
B27: GRUPOS:
B29: Grupo 1 | D29: Grupo 2 | F29: Grupo 3 | H29: Grupo 4
B30: Argentina | D30: Países Bajos | F30: Canadá | H30: Nueva Zelanda
B31: Francia | D31: Bélgica | F31: Qatar | H31: Curazao
B32: Brasil | D32: Croacia | F32: Arabia Saudí | H32: Haití
B33: Inglaterra | D33: Uruguay | F33: Costa de Marfil | H33: Irak
B34: España | D34: Colombia | F34: Ghana | H34: R.D. Congo
B35: Alemania | D35: Marruecos | F35: Sudáfrica | H35: Qatar
B36: Portugal | D36: México | F36: Escocia
D37: Estados Unidos | F37: Chequia
D38: Japón | F38: Turquía
D39: Suiza | F39: Bosnia y Herzegovina
D40: Austria | F40: Uzbekistán
D41: Ecuador | F41: Jordania
D42: Corea del Sur | F42: Cabo Verde
D43: Irán | F43: Panamá
D44: Australia
D45: Paraguay
D46: Túnez
D47: Argelia
...

Sheet Participantes
B2: Participante | C2: TOTALES | D2: Equipo 1 | E2: PTS E1 | F2: Equipo 2 | G2: PTS E2 | H2: Equipo 3 | I2: PTS E3 | J2: Equipo 4 | K2: PTS E4 | L2: Equipo 5 | M2: PTS E5 | N2: Equipo 6 | O2: PTS E6 | P2: Equipo 7 | Q2: PTS E7
B3: Gorka | C3: =SUM(E3+G3+I3+K3+M3+O3+Q3) -> 107 | D3: España | E3: =VLOOKUP(Participantes!D3,Resultados!$B$2:$C$50,2,FALSE) -> 5 | F3: Colombia | G3: =VLOOKUP(Participantes!F3,Resultados!$B$2:$C$50,2,FALSE) -> 12 | H3: Marruecos | I3: =VLOOKUP(Participantes!H3,Resultados!$B$2:$C$50,2,FALSE) -> 13 | J3: México | K3: =VLOOKUP(Participantes!J3,Resultados!$B$2:$C$50,2,FALSE) -> 14 | L3: Corea del Sur | M3: =VLOOKUP(Participantes!L3,Resultados!$B$2:$C$50,2,FALSE) -> 20 | N3: Irán | O3: =VLOOKUP(Participantes!N3,Resultados!$B$2:$C$50,2,FALSE) -> 21 | P3: Australia | Q3: =VLOOKUP(Participantes!P3,Resultados!$B$2:$C$50,2,FALSE) -> 22

Sheet Resultados
B2: Equipo | C2: TOTAL | D2: Jornada 1 - FG3 | E2: Jornada 2 - FG2 | F2: Jornada 3 - FG3 | G2: Dieciseisavos | H2: Octavos | I2: Cuartos | J2: Semifinal | K2: Final
B3: Argentina | C3: =SUM(D3:K3) -> 8 | D3: 1 | E3: 1 | F3: 1 | G3: 1 | H3: 1 | I3: 1 | J3: 1 | K3: 1
B4: Francia | C4: =SUM(D4:K4) -> 2 | D4: 2
B5: Brasil | C5: =SUM(D5:K5) -> 3 | D5: 3
B6: Inglaterra | C6: =SUM(D6:K6) -> 4 | D6: 4
B7: España | C7: =SUM(D7:K7) -> 5 | D7: 5
B8: Alemania | C8: =SUM(D8:K8) -> 6 | D8: 6
B9: Portugal | C9: =SUM(D9:K9) -> 7 | D9: 7
B10: Países Bajos | C10: =SUM(D10:K10) -> 8 | D10: 8
B11: Bélgica | C11: =SUM(D11:K11) -> 9 | D11: 9
B12: Croacia | C12: =SUM(D12:K12) -> 10 | D12: 10
B13: Uruguay | C13: =SUM(D13:K13) -> 11 | D13: 11
B14: Colombia | C14: =SUM(D14:K14) -> 12 | D14: 12
B15: Marruecos | C15: =SUM(D15:K15) -> 13 | D15: 13
... B50: Qatar | C50: =SUM(D50:K50) -> 48 | D50: 48

Sheet Clasificación
B2: Participante | C2: Puntos
B3: =Participantes!B3 -> Gorka | C3: =Participantes!C3 -> 107
B4: =Participantes!B4 -> 0 | C4: =Participantes!C4 -> 0
B5: =Participantes!B5 -> 0 | C5: =Participantes!C5 -> 0
B6: =Participantes!B6 -> 0 | C6: =Participantes!C6 -> 0
B7: =Participantes!B7 -> 0 | C7: =Participantes!C7 -> 0
B8: =Participantes!B8 -> 0 | C8: =Participantes!C8 -> 0
B9: =Participantes!B9 -> 0 | C9: =Participantes!C9 -> 0
B10: =Participantes!B10 -> 0 | C10: =Participantes!C10 -> 0
B11: =Participantes!B11 -> 0 | C11: =Participantes!C11 -> 0
B12: =Participantes!B12 -> 0 | C12: =Participantes!C12 -> 0
B13: =Participantes!B13 -> 0 | C13: =Participantes!C13 -> 0
B14: =Participantes!B14 -> 0 | C14: =Participantes!C14 -> 0
... B31: =Participantes!B31 -> 0 | C31: =Participantes!C31 -> 0
